Workbook
Name LocationList: #REF!

Sheet Location
A1: NAME | B1: CITY | C1: COUNTRY | D1: LATITUDE | E1: LONGITUDE
A2: Brasília Geral | B2: Brasília - DF | C2: Brasil | D2: -15.8117 | E2: -47.9506
A3: Samambaia | B3: Brasília - DF | C3: Brasil | D3: -15.9239 | E3: -48.1719
A4: RNP - Belo Horizonte | B4: Belo Horizonte - MG | C4: Brasil | D4: -19.8692 | E4: -43.9644
A5: Bandeirantes | B5: - | C5: Brasil | D5: -19.9175 | E5: -54.3719
A6: Mirueira | B6: Paulista - PE | C6: Brasil | D6: -7.955 | E6: -34.8917
A7: Banabuiu | B7: Banabuiú - CE | C7: Brasil | D7: -5.30556 | E7: -38.9131
A8: Vitória | B8: Serra - ES | C8: Brasil | D8: -20.1919 | E8: -40.2947
A9: Barreiro | B9: Belo Horizonte - MG | C9: Brasil | D9: -20.0008 | E9: -43.9925
A10: Campos dos Goytacazes | B10: Campos dos Goytacazes - RJ | C10: Brasil | D10: -21.7217 | E10: -41.3397
A11: Campo Maior | B11: Campo Maior - PI | C11: Brasil | D11: -4.81556 | E11: -42.2014
A12: Presidente Tancredo Neves | B12: Presidente Tancredo Neves - BA | C12: Brasil | D12: -13.3692 | E12: -39.3803
A13: Universidade Federal de Mato Grosso do Sul | B13: Campo Grande - MS | C13: Brasil | D13: -20.5025 | E13: -54.6131
... A219: Ariquemes | B219: Ariquemes - RO | C219: Brasil | D219: -9.9275 | E219: -63.0108
A220: Comodoro | D220: -13.9303 | E220: -59.5097
A221: Macapá TIM | B221: Macapá | C221: Brasil | D221: 0.0533333 | E221: -51.0556
A222: Macapá Sub | D222: 0.0988889 | E222: -51.1217
D223: -0.0058333 | E223: -51.0847
D224: -0.811667 | E224: -52.4819
D225: -8.83472 | E225: -63.9394

Sheet Network Elements
A1: ID | B1: CODE | C1: NAME | D1: COLLECTOR IP | E1: COLLECTOR NAME | F1: LOCATION CODE | G1: LOCATION NAME
A2: 1 | B2: 132 | C2: 01-DWRO-CAS01-03-CAMPINAS | D2: 10.66.232.34 | E2: 08.3 - Campinas Rack 5 - Araraquara | F2: SPCAS0PP001 | G2: =IFERROR(VLOOKUP(D2,Location!B:E,7,FALSE),"")
A3: 2 | B3: 133 | C3: 02-DWOA-ARQ01-01-ARARAQUARA | D3: 10.66.232.34 | E3: 08.3 - Campinas Rack 5 - Araraquara | F3: SPARQ0PP001 | G3: =IFERROR(VLOOKUP(D3,Location!B:E,7,FALSE),"")
A4: 3 | B4: 196 | C4: 01-DWRO-JBO01-03-JABOATAO | D4: 10.67.142.34 | E4: 09.2 - Recife - Bongi | F4: PEJBO0PP001 | G4: =IFERROR(VLOOKUP(D4,Location!B:E,7,FALSE),"")
A5: 4 | B5: 197 | C5: 02-DWOA-RCE01-01-BONGI | D5: 10.67.142.34 | E5: 09.2 - Recife - Bongi | F5: PERCE0PP001 | G5: =IFERROR(VLOOKUP(D5,Location!B:E,7,FALSE),"")
A6: 5 | B6: 1023 | C6: 03-DWDT-RCE06-01-CENTRAL-METRO-RECIFE | D6: 10.67.142.34 | E6: 09.2 - Recife - Bongi | F6: PERCE0PM006 | G6: =IFERROR(VLOOKUP(D6,Location!B:E,7,FALSE),"")
A7: 6 | B7: 293 | C7: 01-DWRO-CAS01-01-CAMPINAS | D7: 10.66.226.42 | E7: 08.1 - Campinas - Barueri | F7: SPCAS0PP001 | G7: =IFERROR(VLOOKUP(D7,Location!B:E,7,FALSE),"")
A8: 7 | B8: 294 | C8: 02-DWRO-BRE01-02-BARUERI | D8: 10.66.226.42 | E8: 08.1 - Campinas - Barueri | F8: SPBRE0PP001 | G8: =IFERROR(VLOOKUP(D8,Location!B:E,7,FALSE),"")
A9: 8 | B9: 426 | C9: 01-DWRO-BHE01-01-BARREIRO | D9: 10.79.233.1 | E9: 14.1 - BARREIRO - BETIM | F9: MGBHE0PP001 | G9: =IFERROR(VLOOKUP(D9,Location!B:E,7,FALSE),"")
A10: 9 | B10: 662 | C10: 02-DWRO-BET01-02-REGAP-BETIM | D10: 10.79.233.1 | E10: 14.1 - BARREIRO - BETIM | F10: MGBET0PP001 | G10: =IFERROR(VLOOKUP(D10,Location!B:E,7,FALSE),"")
A11: 10 | B11: 442 | C11: 04-DWRO-BHE01-02-BARREIRO | D11: 10.79.233.33 | E11: BARREIRO - FURNAS | F11: MGBHE0PP001 | G11: =IFERROR(VLOOKUP(D11,Location!B:E,7,FALSE),"")
A12: 11 | B12: 443 | C12: 03-DWOA-DVL01-01-CARMO-DO-CAJURU | D12: 10.79.233.33 | E12: BARREIRO - FURNAS | F12: MGDVL0PP001 | G12: =IFERROR(VLOOKUP(D12,Location!B:E,7,FALSE),"")
A13: 12 | B13: 444 | C13: 02-DWOA-PMN01-01-PIMENTA | D13: 10.79.233.33 | E13: BARREIRO - FURNAS | F13: MGPMN0PP001 | G13: =IFERROR(VLOOKUP(D13,Location!B:E,7,FALSE),"")
... A84: 83 | B84: 1620 | C84: 03-DWOA-CGE01-01-CAMPINA-GRANDE | D84: 10.67.152.26 | E84: 12.2 Natal (Lagoa Nova) - Mirueira - 2 | F84: PBCGE0PP001 | G84: =IFERROR(VLOOKUP(D84,Location!B:E,7,FALSE),"")
A85: 84 | B85: 1626 | C85: 07-DWOA-SMS01-01-SANTANA-DOS-MATOS | D85: 10.79.243.36 | E85: 12 - Fortaleza - Natal - 4 | G85: =IFERROR(VLOOKUP(D85,Location!B:E,7,FALSE),"")
A86: 85 | B86: 1628 | C86: 08-DWOA-SNZ01-01-SANTA-CRUZ | D86: 10.79.243.36 | E86: 12 - Fortaleza - Natal - 4 | G86: =IFERROR(VLOOKUP(D86,Location!B:E,7,FALSE),"")
A87: 86 | B87: 1631 | C87: 05-DWOA-MRO01-01-MOSSORO | D87: 192.168.103.10 | E87: 12 - Fortaleza - Natal - 3 | F87: RNMRO0PP001 | G87: =IFERROR(VLOOKUP(D87,Location!B:E,7,FALSE),"")
A88: 87 | B88: 1632 | C88: 06-DWOA-ACU01-01-ACU | D88: 192.168.103.10 | E88: 12 - Fortaleza - Natal - 3 | F88: RNACU0PP001 | G88: =IFERROR(VLOOKUP(D88,Location!B:E,7,FALSE),"")
A89: 88 | B89: 1635 | C89: 01-DWRO-FLA01-02-FORTALEZA | D89: 192.168.102.234 | E89: 12 - Fortaleza - Natal - 1 | F89: CEFLA0PP001 | G89: =IFERROR(VLOOKUP(D89,Location!B:E,7,FALSE),"")
A90: 89 | B90: 1636 | C90: 02-DWOA-AAB01-01-ARACOIABA | D90: 192.168.102.234 | E90: 12 - Fortaleza - Natal - 1 | F90: CEAAB0PP001 | G90: =IFERROR(VLOOKUP(D90,Location!B:E,7,FALSE),"")
A91: 90 | B91: 1638 | C91: 03-DWRO-BIU01-01-BANABUIU | D91: 192.168.102.250 | E91: 12 - Fortaleza - Natal - 2 | F91: CEBIU0PP001 | G91: =IFERROR(VLOOKUP(D91,Location!B:E,7,FALSE),"")
A92: 91 | B92: 1639 | C92: 04-DWOA-RUS01-01-RUSSAS | D92: 192.168.102.250 | E92: 12 - Fortaleza - Natal - 2 | F92: CERUS0PP001 | G92: =IFERROR(VLOOKUP(D92,Location!B:E,7,FALSE),"")
A93: 92 | B93: 1641 | C93: 09-DWRO-NTL01-01-NATAL | D93: 192.168.103.26 | E93: 12 - Fortaleza - Natal - 5 | F93: RNNTL0PP001 | G93: =IFERROR(VLOOKUP(D93,Location!B:E,7,FALSE),"")
A94: 93 | B94: 1651 | C94: 01-DWRO-NTL01-02-NATAL | D94: 10.66.0.18 | E94: 12.1 Natal (Lagoa Nova) - Natal - 1 | F94: RNNTL0PP001 | G94: =IFERROR(VLOOKUP(D94,Location!B:E,7,FALSE),"")
A95: 94 | B95: 1652 | C95: 02-DWDT-NTL02-01-LAGOA-NOVA | D95: 10.66.0.18 | E95: 12.1 Natal (Lagoa Nova) - Natal - 1 | F95: RNNTL0PP002 | G95: =IFERROR(VLOOKUP(D95,Location!B:E,7,FALSE),"")
A96: 95 | B96: 1655 | C96: 01-DWDT-NTL02-02-LAGOA-NOVA | D96: 10.66.0.26 | E96: 12.2 Natal (Lagoa Nova) - Mirueira - 1 | F96: RNNTL0PP002 | G96: =IFERROR(VLOOKUP(D96,Location!B:E,7,FALSE),"")
A97: 96 | B97: 1656 | C97: 02-DWOA-TAM01-01-CAMPO-DE-SANTANA | D97: 10.66.0.26 | E97: 12.2 Natal (Lagoa Nova) - Mirueira - 1 | F97: PBTAM0PP001 | G97: =IFERROR(VLOOKUP(D97,Location!B:E,7,FALSE),"")
A98: 97 | B98: 1666 | C98: 15-DWRO-MCW01-01-MARACANAU | D98: 10.79.118.33 | E98: 13.1 - IMPERATRIZ - MARACANAU 7 | F98: CEMCW0PP001 | G98: =IFERROR(VLOOKUP(D98,Location!B:E,7,FALSE),"")
... A128: 127 | B128: 1853 | C128: 01-DWRO-FLA01-03-FORTALEZA | D128: 10.79.118.66 | E128: 13.2.1 - METRO - FORTALEZA - CASTELAO 1 | F128: CEFLA0PP001 | G128: =IFERROR(VLOOKUP(D128,Location!B:E,7,FALSE),"")
A129: 128 | B129: 1854 | C129: 02-DWTR-FLA03-02-CASTELAO | D129: 10.79.118.66 | E129: 13.2.1 - METRO - FORTALEZA - CASTELAO 1 | G129: =IFERROR(VLOOKUP(D129,Location!B:E,7,FALSE),"")
A130: 129 | B130: 1857 | C130: 04-DWRO-MCW01-03-MARACANAU | D130: 10.79.118.65 | E130: 13.2.1 - METRO - FORTALEZA - CASTELAO 2 | F130: CEMCW0PP001 | G130: =IFERROR(VLOOKUP(D130,Location!B:E,7,FALSE),"")
A131: 130 | B131: 1858 | C131: 03-DWTR-FLA03-01-CASTELAO | D131: 10.79.118.65 | E131: 13.2.1 - METRO - FORTALEZA - CASTELAO 2 | G131: =IFERROR(VLOOKUP(D131,Location!B:E,7,FALSE),"")
A132: 131 | B132: 1884 | C132: 01-DWRO-BSA02-01-SAMAMBAIA | D132: 10.67.226.18 | E132: 02 - Itumbiara_Samambaia 1 | F132: DFBSA0PP002 | G132: =IFERROR(VLOOKUP(D132,Location!B:E,7,FALSE),"")
A133: 132 | B133: 1885 | C133: 02-DWOA-ANS01-01-PIRINEUS | D133: 10.67.226.18 | E133: 02 - Itumbiara_Samambaia 1 | F133: GOANS0PP001 | G133: =IFERROR(VLOOKUP(D133,Location!B:E,7,FALSE),"")
A134: 133 | B134: 1887 | C134: 03-DWRO-ACG01-01-BANDEIRANTES | D134: 10.67.226.20 | E134: 02 - Itumbiara_Samambaia 2 | F134: GOACG0PP001 | G134: =IFERROR(VLOOKUP(D134,Location!B:E,7,FALSE),"")
A135: 134 | B135: 1888 | C135: 04-DWOA-MIH02-01-MORRINHOS | D135: 10.67.226.20 | E135: 02 - Itumbiara_Samambaia 2 | F135: GOMIH0PP002 | G135: =IFERROR(VLOOKUP(D135,Location!B:E,7,FALSE),"")
A136: 135 | B136: 1893 | C136: 01-DWRO-GTI01-03-GRAVATAI-TLB | D136: 10.66.168.34 | E136: 17.3.1 - METRO POA - GRAVATAI TLB - BEIRA RIO | F136: RSGTI0PP001 | G136: =IFERROR(VLOOKUP(D136,Location!B:E,7,FALSE),"")
A137: 136 | B137: 1930 | C137: 02-DWDT-PAE02-01-PROCERGS | D137: 10.66.168.34 | E137: 17.3.1 - METRO POA - GRAVATAI TLB - BEIRA RIO | F137: RSPAE0PM002 | G137: =IFERROR(VLOOKUP(D137,Location!B:E,7,FALSE),"")
A138: 137 | B138: 1896 | C138: 02-DWOA-PRT01-01-PRATA | D138: 10.67.70.18 | E138: 02.1 - Itumbiara_Furnas 1 | F138: MGPRT0PP001 | G138: =IFERROR(VLOOKUP(D138,Location!B:E,7,FALSE),"")
A139: 138 | B139: 1897 | C139: 01-DWRO-ARPO2-01-ITUMBIARA | D139: 10.67.70.18 | E139: 02.1 - Itumbiara_Furnas 1 | F139: MGARPOPP002 | G139: =IFERROR(VLOOKUP(D139,Location!B:E,7,FALSE),"")
...
